2025-09-03 11:40:49,398 [ERROR] Account[nosomename]: Error handling message: Could not find the input entity for PeerChannel(channel_id=3024795981) (PeerChannel). Please read https://docs.telethon.dev/en/stable/concepts/entities.html to find out more details.
Traceback (most recent call last):
  File "/Users/some/App/forwarding_bot/src/account_worker.py", line 164, in _on_new_message
    dest = await self.resolve_target(dest_ref)
  File "/Users/some/App/forwarding_bot/src/account_worker.py", line 59, in resolve_target
    ent = await self.client.get_entity(normalize_chat_ref(target))
  File "/Users/some/App/forwarding_bot/venv/lib/python3.9/site-packages/telethon/client/users.py", line 298, in get_entity
    inputs.append(await self.get_input_entity(x))
  File "/Users/some/App/forwarding_bot/venv/lib/python3.9/site-packages/telethon/client/users.py", line 474, in get_input_entity
    raise ValueError(
ValueError: Could not find the input entity for PeerChannel(channel_id=3024795981) (PeerChannel). Please read https://docs.telethon.dev/en/stable/concepts/entities.html to find out more details.
